/home/ubuntu/dev/lib/python3.10/site-packages/transformers/models/auto/configuration_auto.py:1020: FutureWarning: The `use_auth_token` argument is deprecated and will be removed in v5 of Transformers.
  warnings.warn(
/home/ubuntu/dev/lib/python3.10/site-packages/transformers/models/auto/auto_factory.py:472: FutureWarning: The `use_auth_token` argument is deprecated and will be removed in v5 of Transformers.
  warnings.warn(














Loading checkpoint shards: 100%|█████████████████████████████████████████████████████████████████████████████████████████████████████████████████████████████████████████████████████████████████████████████████████████████████████████████████| 15/15 [07:57<00:00, 31.85s/it]
/home/ubuntu/dev/lib/python3.10/site-packages/transformers/utils/hub.py:374: FutureWarning: The `use_auth_token` argument is deprecated and will be removed in v5 of Transformers.
  warnings.warn(
Downloading (…)neration_config.json: 100%|███████████████████████████████████████████████████████████████████████████████████████████████████████████████████████████████████████████████████████████████████████████████████████████████████████| 188/188 [00:00<00:00, 603kB/s]
Traceback (most recent call last):
  File "/home/ubuntu/dev/lib/python3.10/site-packages/huggingface_hub/utils/_errors.py", line 261, in hf_raise_for_status
    response.raise_for_status()
  File "/home/ubuntu/dev/lib/python3.10/site-packages/requests/models.py", line 1021, in raise_for_status
    raise HTTPError(http_error_msg, response=self)
requests.exceptions.HTTPError: 401 Client Error: Unauthorized for url: https://huggingface.co/meta-llama/Llama-2-70b-chat-hf/resolve/main/tokenizer_config.json
The above exception was the direct cause of the following exception:
Traceback (most recent call last):
  File "/home/ubuntu/dev/lib/python3.10/site-packages/transformers/utils/hub.py", line 429, in cached_file
    resolved_file = hf_hub_download(
  File "/home/ubuntu/dev/lib/python3.10/site-packages/huggingface_hub/utils/_validators.py", line 118, in _inner_fn
    return fn(*args, **kwargs)
  File "/home/ubuntu/dev/lib/python3.10/site-packages/huggingface_hub/file_download.py", line 1346, in hf_hub_download
    raise head_call_error
  File "/home/ubuntu/dev/lib/python3.10/site-packages/huggingface_hub/file_download.py", line 1232, in hf_hub_download
    metadata = get_hf_file_metadata(
  File "/home/ubuntu/dev/lib/python3.10/site-packages/huggingface_hub/utils/_validators.py", line 118, in _inner_fn
    return fn(*args, **kwargs)
  File "/home/ubuntu/dev/lib/python3.10/site-packages/huggingface_hub/file_download.py", line 1608, in get_hf_file_metadata
    hf_raise_for_status(r)
  File "/home/ubuntu/dev/lib/python3.10/site-packages/huggingface_hub/utils/_errors.py", line 277, in hf_raise_for_status
    raise GatedRepoError(message, response) from e
huggingface_hub.utils._errors.GatedRepoError: 401 Client Error. (Request ID: Root=1-65426aca-799338ea06e127685cd8fbe5;22b87cd6-052b-4583-81ad-187b96bf5709)
Cannot access gated repo for url https://huggingface.co/meta-llama/Llama-2-70b-chat-hf/resolve/main/tokenizer_config.json.
Repo model meta-llama/Llama-2-70b-chat-hf is gated. You must be authenticated to access it.
The above exception was the direct cause of the following exception:
Traceback (most recent call last):
  File "/home/ubuntu/LLM/LLM-as-a-Service/Ray_demo/llmAPI/backend.py", line 413, in <module>
    myllm = PredictDeployment()
  File "/home/ubuntu/LLM/LLM-as-a-Service/Ray_demo/llmAPI/backend.py", line 146, in __init__
    self.tokenizer = transformers.AutoTokenizer.from_pretrained(
  File "/home/ubuntu/dev/lib/python3.10/site-packages/transformers/models/auto/tokenization_auto.py", line 701, in from_pretrained
    tokenizer_config = get_tokenizer_config(pretrained_model_name_or_path, **kwargs)
  File "/home/ubuntu/dev/lib/python3.10/site-packages/transformers/models/auto/tokenization_auto.py", line 534, in get_tokenizer_config
    resolved_config_file = cached_file(
  File "/home/ubuntu/dev/lib/python3.10/site-packages/transformers/utils/hub.py", line 444, in cached_file
    raise EnvironmentError(
OSError: You are trying to access a gated repo.
Make sure to request access at https://huggingface.co/meta-llama/Llama-2-70b-chat-hf and pass a token having permission to this repo either by logging in with `huggingface-cli login` or by passing `token=<your_token>`.
Traceback (most recent call last):
  File "/home/ubuntu/dev/lib/python3.10/site-packages/huggingface_hub/utils/_errors.py", line 261, in hf_raise_for_status
    response.raise_for_status()
  File "/home/ubuntu/dev/lib/python3.10/site-packages/requests/models.py", line 1021, in raise_for_status
    raise HTTPError(http_error_msg, response=self)
requests.exceptions.HTTPError: 401 Client Error: Unauthorized for url: https://huggingface.co/meta-llama/Llama-2-70b-chat-hf/resolve/main/tokenizer_config.json
The above exception was the direct cause of the following exception:
Traceback (most recent call last):
  File "/home/ubuntu/dev/lib/python3.10/site-packages/transformers/utils/hub.py", line 429, in cached_file
    resolved_file = hf_hub_download(
  File "/home/ubuntu/dev/lib/python3.10/site-packages/huggingface_hub/utils/_validators.py", line 118, in _inner_fn
    return fn(*args, **kwargs)
  File "/home/ubuntu/dev/lib/python3.10/site-packages/huggingface_hub/file_download.py", line 1346, in hf_hub_download
    raise head_call_error
  File "/home/ubuntu/dev/lib/python3.10/site-packages/huggingface_hub/file_download.py", line 1232, in hf_hub_download
    metadata = get_hf_file_metadata(
  File "/home/ubuntu/dev/lib/python3.10/site-packages/huggingface_hub/utils/_validators.py", line 118, in _inner_fn
    return fn(*args, **kwargs)
  File "/home/ubuntu/dev/lib/python3.10/site-packages/huggingface_hub/file_download.py", line 1608, in get_hf_file_metadata
    hf_raise_for_status(r)
  File "/home/ubuntu/dev/lib/python3.10/site-packages/huggingface_hub/utils/_errors.py", line 277, in hf_raise_for_status
    raise GatedRepoError(message, response) from e
huggingface_hub.utils._errors.GatedRepoError: 401 Client Error. (Request ID: Root=1-65426aca-799338ea06e127685cd8fbe5;22b87cd6-052b-4583-81ad-187b96bf5709)
Cannot access gated repo for url https://huggingface.co/meta-llama/Llama-2-70b-chat-hf/resolve/main/tokenizer_config.json.
Repo model meta-llama/Llama-2-70b-chat-hf is gated. You must be authenticated to access it.
The above exception was the direct cause of the following exception:
Traceback (most recent call last):
  File "/home/ubuntu/LLM/LLM-as-a-Service/Ray_demo/llmAPI/backend.py", line 413, in <module>
    myllm = PredictDeployment()
  File "/home/ubuntu/LLM/LLM-as-a-Service/Ray_demo/llmAPI/backend.py", line 146, in __init__
    self.tokenizer = transformers.AutoTokenizer.from_pretrained(
  File "/home/ubuntu/dev/lib/python3.10/site-packages/transformers/models/auto/tokenization_auto.py", line 701, in from_pretrained
    tokenizer_config = get_tokenizer_config(pretrained_model_name_or_path, **kwargs)
  File "/home/ubuntu/dev/lib/python3.10/site-packages/transformers/models/auto/tokenization_auto.py", line 534, in get_tokenizer_config
    resolved_config_file = cached_file(
  File "/home/ubuntu/dev/lib/python3.10/site-packages/transformers/utils/hub.py", line 444, in cached_file
    raise EnvironmentError(
OSError: You are trying to access a gated repo.
Make sure to request access at https://huggingface.co/meta-llama/Llama-2-70b-chat-hf and pass a token having permission to this repo either by logging in with `huggingface-cli login` or by passing `token=<your_token>`.